Workbook

Sheet Info
A1: Device tests of 2026-10-30 (raw per-cell values)
A2: Devices / calibration | B2: ibm_kingston (fetch 11:02 CET; at submission 11:54, 12:17); ibm_marrakesh (fetch 10:20; at submission 11:47, 12:08)
A3: Declarations | B3: test 2 echo_hz_note.md 1308cf9b... + addendum 1 a206c81a...; test 3 test3_note.md 8b13773f... + addenda 1c484fa8..., 78986cf3...; QELM A qelm_A_note.md 8c26afd7... + addendum 1 4cfff876... (kingston only)
A4: Billed | B4: marrakesh 67 + 71 + 81 + 54 = 273 s; kingston 65 + 69 + 78 + 53 + 69 + 71 + 70 = 475 s; total 748 s (model about 900 s)
A5: Arms | B5: rule = fold:rule, zipcyc = fold:zipcyc, blind Qiskit = qiskit:2:blind:template (map-free)
A6: Colour | B6: blue = values from the score files (computed from raw_counts.json); black = formulas
A7: Not here | B7: the bit-string counts themselves (raw_counts.json per job, in TOQB results)

Sheet Echo (tests 2, 3E)
A1: device | B1: test | C1: n | D1: hz | E1: D (full depth) | F1: arm | G1: rho_E (weight 1) | H1: SE | I1: signal / SE | J1: weight-2 echo | K1: SE w2 | L1: 2Q gates | M1: duration (us) | N1: readable (> 2 SE)
A2: kingston | B2: 2 | C2: 20 | D2: 0 | E2: 24 | F2: rule | G2: 0.36626039 | H2: 0.010780172 | I2: =G2/H2 -> 33.975376 | J2: 0.43846874 | K2: 0.0093412092 | L2: 480 | M2: 7.332 | N2: =IF(G2>2*H2,"yes","no") -> yes
A3: kingston | B3: 2 | C3: 20 | D3: 0 | E3: 24 | F3: zipcyc | G3: 0.079050979 | H3: 0.0075944396 | I3: =G3/H3 -> 10.40906 | J3: 0.15077373 | K3: 0.0068438244 | L3: 1104 | M3: 14.82 | N3: =IF(G3>2*H3,"yes","no") -> yes
A4: kingston | B4: 2 | C4: 20 | D4: 0 | E4: 24 | F4: blind Qiskit | G4: -0.03070858 | H4: 0.006048424 | I4: =G4/H4 -> -5.0771209 | J4: 0.13179129 | K4: 0.0054450041 | L4: 480 | M4: 37.668 | N4: =IF(G4>2*H4,"yes","no") -> no
A5: kingston | B5: 2 | C5: 20 | D5: 0 | E5: 50 | F5: rule | G5: 0.098586518 | H5: 0.0085064702 | I5: =G5/H5 -> 11.589592 | J5: 0.21464278 | K5: 0.0075334345 | L5: 1000 | M5: 12.844 | N5: =IF(G5>2*H5,"yes","no") -> yes
A6: kingston | B6: 2 | C6: 20 | D6: 0 | E6: 50 | F6: zipcyc | G6: -0.00040897705 | H6: 0.0054398265 | I6: =G6/H6 -> -0.075182001 | J6: 0.036673284 | K6: 0.0054072763 | L6: 2300 | M6: 28.444 | N6: =IF(G6>2*H6,"yes","no") -> no
A7: kingston | B7: 2 | C7: 20 | D7: 0 | E7: 50 | F7: blind Qiskit | G7: 0.00067361003 | H7: 0.0053640949 | I7: =G7/H7 -> 0.12557757 | J7: 0.026542016 | K7: 0.0053983944 | L7: 1000 | M7: 76.044 | N7: =IF(G7>2*H7,"yes","no") -> no
A8: kingston | B8: 2 | C8: 20 | D8: 0 | E8: 100 | F8: rule | G8: 0.0069568776 | H8: 0.005896675 | I8: =G8/H8 -> 1.1797967 | J8: 0.092108018 | K8: 0.0056595189 | L8: 2000 | M8: 23.444 | N8: =IF(G8>2*H8,"yes","no") -> no
A9: kingston | B9: 2 | C9: 20 | D9: 0 | E9: 100 | F9: zipcyc | G9: 0.011092368 | H9: 0.0051106539 | I9: =G9/H9 -> 2.1704401 | J9: 0.0073175831 | K9: 0.0052311542 | L9: 4600 | M9: 54.644 | N9: =IF(G9>2*H9,"yes","no") -> yes
A10: kingston | B10: 2 | C10: 20 | D10: 0 | E10: 100 | F10: blind Qiskit | G10: 0.0062674816 | H10: 0.005214468 | I10: =G10/H10 -> 1.2019408 | J10: 0.0035419126 | K10: 0.0053621683 | L10: 2000 | M10: 149.844 | N10: =IF(G10>2*H10,"yes","no") -> no
A11: kingston | B11: 2 | C11: 20 | D11: 0.1 | E11: 24 | F11: rule | G11: 0.38737725 | H11: 0.010181549 | I11: =G11/H11 -> 38.046985 | J11: 0.45238594 | K11: 0.0088983096 | L11: 480 | M11: 7.332 | N11: =IF(G11>2*H11,"yes","no") -> yes
A12: kingston | B12: 2 | C12: 20 | D12: 0.1 | E12: 24 | F12: zipcyc | G12: 0.073636271 | H12: 0.0070523203 | I12: =G12/H12 -> 10.441425 | J12: 0.13742537 | K12: 0.0066537612 | L12: 1104 | M12: 14.82 | N12: =IF(G12>2*H12,"yes","no") -> yes
A13: kingston | B13: 2 | C13: 20 | D13: 0.1 | E13: 24 | F13: blind Qiskit | G13: -0.014420583 | H13: 0.0059427458 | I13: =G13/H13 -> -2.4265859 | J13: 0.10151792 | K13: 0.0055481534 | L13: 480 | M13: 37.668 | N13: =IF(G13>2*H13,"yes","no") -> no
... A217: marrakesh | B217: 3E | C217: 72 | D217: 0.3 | E217: 100 | F217: blind Qiskit | G217: -0.0038199463 | H217: 0.0028106459 | I217: =G217/H217 -> -1.3590991 | J217: -0.0037883532 | K217: 0.0029758414 | L217: 7200 | M217: 508.356 | N217: =IF(G217>2*H217,"yes","no") -> no

Sheet Echo rule vs others
A1: device | B1: test | C1: n | D1: hz | E1: D | F1: other | G1: rho rule | H1: SE rule | I1: rho other | J1: SE other | K1: diff | L1: SE diff | M1: z | N1: judged? (either > 2 SE) | O1: verdict
A2: kingston | B2: 2 | C2: 20 | D2: 0 | E2: 24 | F2: zipcyc | G2: ='Echo (tests 2, 3E)'!G2 -> 0.36626039 | H2: ='Echo (tests 2, 3E)'!H2 -> 0.010780172 | I2: ='Echo (tests 2, 3E)'!G3 -> 0.079050979 | J2: ='Echo (tests 2, 3E)'!H3 -> 0.0075944396 | K2: =G2-I2 -> 0.28720941 | L2: =SQRT(H2^2+J2^2) -> 0.013186646 | M2: =K2/L2 -> 21.780324 | N2: =IF(OR(G2>2*H2,I2>2*J2),"yes","no") -> yes | O2: =IF(N2="no","NOT JUDGED",IF(K2>2*L2,"WIN",IF(K2<-2*L2,"LOSS","TIE"))) -> WIN
A3: kingston | B3: 2 | C3: 20 | D3: 0 | E3: 24 | F3: blind Qiskit | G3: ='Echo (tests 2, 3E)'!G2 -> 0.36626039 | H3: ='Echo (tests 2, 3E)'!H2 -> 0.010780172 | I3: ='Echo (tests 2, 3E)'!G4 -> -0.03070858 | J3: ='Echo (tests 2, 3E)'!H4 -> 0.006048424 | K3: =G3-I3 -> 0.39696897 | L3: =SQRT(H3^2+J3^2) -> 0.012361049 | M3: =K3/L3 -> 32.114504 | N3: =IF(OR(G3>2*H3,I3>2*J3),"yes","no") -> yes | O3: =IF(N3="no","NOT JUDGED",IF(K3>2*L3,"WIN",IF(K3<-2*L3,"LOSS","TIE"))) -> WIN
A4: kingston | B4: 2 | C4: 20 | D4: 0 | E4: 50 | F4: zipcyc | G4: ='Echo (tests 2, 3E)'!G5 -> 0.098586518 | H4: ='Echo (tests 2, 3E)'!H5 -> 0.0085064702 | I4: ='Echo (tests 2, 3E)'!G6 -> -0.00040897705 | J4: ='Echo (tests 2, 3E)'!H6 -> 0.0054398265 | K4: =G4-I4 -> 0.098995495 | L4: =SQRT(H4^2+J4^2) -> 0.010097116 | M4: =K4/L4 -> 9.804334 | N4: =IF(OR(G4>2*H4,I4>2*J4),"yes","no") -> yes | O4: =IF(N4="no","NOT JUDGED",IF(K4>2*L4,"WIN",IF(K4<-2*L4,"LOSS","TIE"))) -> WIN
A5: kingston | B5: 2 | C5: 20 | D5: 0 | E5: 50 | F5: blind Qiskit | G5: ='Echo (tests 2, 3E)'!G5 -> 0.098586518 | H5: ='Echo (tests 2, 3E)'!H5 -> 0.0085064702 | I5: ='Echo (tests 2, 3E)'!G7 -> 0.00067361003 | J5: ='Echo (tests 2, 3E)'!H7 -> 0.0053640949 | K5: =G5-I5 -> 0.097912908 | L5: =SQRT(H5^2+J5^2) -> 0.010056518 | M5: =K5/L5 -> 9.7362637 | N5: =IF(OR(G5>2*H5,I5>2*J5),"yes","no") -> yes | O5: =IF(N5="no","NOT JUDGED",IF(K5>2*L5,"WIN",IF(K5<-2*L5,"LOSS","TIE"))) -> WIN
A6: kingston | B6: 2 | C6: 20 | D6: 0 | E6: 100 | F6: zipcyc | G6: ='Echo (tests 2, 3E)'!G8 -> 0.0069568776 | H6: ='Echo (tests 2, 3E)'!H8 -> 0.005896675 | I6: ='Echo (tests 2, 3E)'!G9 -> 0.011092368 | J6: ='Echo (tests 2, 3E)'!H9 -> 0.0051106539 | K6: =G6-I6 -> -0.0041354907 | L6: =SQRT(H6^2+J6^2) -> 0.0078031762 | M6: =K6/L6 -> -0.5299753 | N6: =IF(OR(G6>2*H6,I6>2*J6),"yes","no") -> yes | O6: =IF(N6="no","NOT JUDGED",IF(K6>2*L6,"WIN",IF(K6<-2*L6,"LOSS","TIE"))) -> TIE
A7: kingston | B7: 2 | C7: 20 | D7: 0 | E7: 100 | F7: blind Qiskit | G7: ='Echo (tests 2, 3E)'!G8 -> 0.0069568776 | H7: ='Echo (tests 2, 3E)'!H8 -> 0.005896675 | I7: ='Echo (tests 2, 3E)'!G10 -> 0.0062674816 | J7: ='Echo (tests 2, 3E)'!H10 -> 0.005214468 | K7: =G7-I7 -> 0.00068939598 | L7: =SQRT(H7^2+J7^2) -> 0.0078715597 | M7: =K7/L7 -> 0.087580607 | N7: =IF(OR(G7>2*H7,I7>2*J7),"yes","no") -> no | O7: =IF(N7="no","NOT JUDGED",IF(K7>2*L7,"WIN",IF(K7<-2*L7,"LOSS","TIE"))) -> NOT JUDGED
A8: kingston | B8: 2 | C8: 20 | D8: 0.1 | E8: 24 | F8: zipcyc | G8: ='Echo (tests 2, 3E)'!G11 -> 0.38737725 | H8: ='Echo (tests 2, 3E)'!H11 -> 0.010181549 | I8: ='Echo (tests 2, 3E)'!G12 -> 0.073636271 | J8: ='Echo (tests 2, 3E)'!H12 -> 0.0070523203 | K8: =G8-I8 -> 0.31374098 | L8: =SQRT(H8^2+J8^2) -> 0.012385442 | M8: =K8/L8 -> 25.331433 | N8: =IF(OR(G8>2*H8,I8>2*J8),"yes","no") -> yes | O8: =IF(N8="no","NOT JUDGED",IF(K8>2*L8,"WIN",IF(K8<-2*L8,"LOSS","TIE"))) -> WIN
A9: kingston | B9: 2 | C9: 20 | D9: 0.1 | E9: 24 | F9: blind Qiskit | G9: ='Echo (tests 2, 3E)'!G11 -> 0.38737725 | H9: ='Echo (tests 2, 3E)'!H11 -> 0.010181549 | I9: ='Echo (tests 2, 3E)'!G13 -> -0.014420583 | J9: ='Echo (tests 2, 3E)'!H13 -> 0.0059427458 | K9: =G9-I9 -> 0.40179783 | L9: =SQRT(H9^2+J9^2) -> 0.011788985 | M9: =K9/L9 -> 34.082479 | N9: =IF(OR(G9>2*H9,I9>2*J9),"yes","no") -> yes | O9: =IF(N9="no","NOT JUDGED",IF(K9>2*L9,"WIN",IF(K9<-2*L9,"LOSS","TIE"))) -> WIN
A10: kingston | B10: 2 | C10: 20 | D10: 0.1 | E10: 50 | F10: zipcyc | G10: ='Echo (tests 2, 3E)'!G14 -> 0.10412303 | H10: ='Echo (tests 2, 3E)'!H14 -> 0.0082911052 | I10: ='Echo (tests 2, 3E)'!G15 -> 0.011839755 | J10: ='Echo (tests 2, 3E)'!H15 -> 0.0052549127 | K10: =G10-I10 -> 0.092283272 | L10: =SQRT(H10^2+J10^2) -> 0.0098161364 | M10: =K10/L10 -> 9.4011807 | N10: =IF(OR(G10>2*H10,I10>2*J10),"yes","no") -> yes | O10: =IF(N10="no","NOT JUDGED",IF(K10>2*L10,"WIN",IF(K10<-2*L10,"LOSS","TIE"))) -> WIN
A11: kingston | B11: 2 | C11: 20 | D11: 0.1 | E11: 50 | F11: blind Qiskit | G11: ='Echo (tests 2, 3E)'!G14 -> 0.10412303 | H11: ='Echo (tests 2, 3E)'!H14 -> 0.0082911052 | I11: ='Echo (tests 2, 3E)'!G16 -> 5.1851084e-05 | J11: ='Echo (tests 2, 3E)'!H16 -> 0.0053286298 | K11: =G11-I11 -> 0.10407118 | L11: =SQRT(H11^2+J11^2) -> 0.0098557963 | M11: =K11/L11 -> 10.559388 | N11: =IF(OR(G11>2*H11,I11>2*J11),"yes","no") -> yes | O11: =IF(N11="no","NOT JUDGED",IF(K11>2*L11,"WIN",IF(K11<-2*L11,"LOSS","TIE"))) -> WIN
A12: kingston | B12: 2 | C12: 20 | D12: 0.1 | E12: 100 | F12: zipcyc | G12: ='Echo (tests 2, 3E)'!G17 -> 0.00056211355 | H12: ='Echo (tests 2, 3E)'!H17 -> 0.0057525642 | I12: ='Echo (tests 2, 3E)'!G18 -> -0.00020438404 | J12: ='Echo (tests 2, 3E)'!H18 -> 0.0050107545 | K12: =G12-I12 -> 0.00076649758 | L12: =SQRT(H12^2+J12^2) -> 0.0076288699 | M12: =K12/L12 -> 0.10047328 | N12: =IF(OR(G12>2*H12,I12>2*J12),"yes","no") -> no | O12: =IF(N12="no","NOT JUDGED",IF(K12>2*L12,"WIN",IF(K12<-2*L12,"LOSS","TIE"))) -> NOT JUDGED
A13: kingston | B13: 2 | C13: 20 | D13: 0.1 | E13: 100 | F13: blind Qiskit | G13: ='Echo (tests 2, 3E)'!G17 -> 0.00056211355 | H13: ='Echo (tests 2, 3E)'!H17 -> 0.0057525642 | I13: ='Echo (tests 2, 3E)'!G19 -> 0.01011201 | J13: ='Echo (tests 2, 3E)'!H19 -> 0.0051142596 | K13: =G13-I13 -> -0.0095498964 | L13: =SQRT(H13^2+J13^2) -> 0.0076972492 | M13: =K13/L13 -> -1.2406895 | N13: =IF(OR(G13>2*H13,I13>2*J13),"yes","no") -> no | O13: =IF(N13="no","NOT JUDGED",IF(K13>2*L13,"WIN",IF(K13<-2*L13,"LOSS","TIE"))) -> NOT JUDGED
A14: kingston | B14: 2 | C14: 20 | D14: 0.3 | E14: 24 | F14: zipcyc | G14: ='Echo (tests 2, 3E)'!G20 -> 0.40169543 | H14: ='Echo (tests 2, 3E)'!H20 -> 0.0097124504 | I14: ='Echo (tests 2, 3E)'!G21 -> 0.096484056 | J14: ='Echo (tests 2, 3E)'!H21 -> 0.0069815129 | K14: =G14-I14 -> 0.30521138 | L14: =SQRT(H14^2+J14^2) -> 0.011961322 | M14: =K14/L14 -> 25.516526 | N14: =IF(OR(G14>2*H14,I14>2*J14),"yes","no") -> yes | O14: =IF(N14="no","NOT JUDGED",IF(K14>2*L14,"WIN",IF(K14<-2*L14,"LOSS","TIE"))) -> WIN
A15: kingston | B15: 2 | C15: 20 | D15: 0.3 | E15: 24 | F15: blind Qiskit | G15: ='Echo (tests 2, 3E)'!G20 -> 0.40169543 | H15: ='Echo (tests 2, 3E)'!H20 -> 0.0097124504 | I15: ='Echo (tests 2, 3E)'!G22 -> 0.016704711 | J15: ='Echo (tests 2, 3E)'!H22 -> 0.0056385081 | K15: =G15-I15 -> 0.38499072 | L15: =SQRT(H15^2+J15^2) -> 0.011230515 | M15: =K15/L15 -> 34.280772 | N15: =IF(OR(G15>2*H15,I15>2*J15),"yes","no") -> yes | O15: =IF(N15="no","NOT JUDGED",IF(K15>2*L15,"WIN",IF(K15<-2*L15,"LOSS","TIE"))) -> WIN
A16: kingston | B16: 2 | C16: 20 | D16: 0.3 | E16: 50 | F16: zipcyc | G16: ='Echo (tests 2, 3E)'!G23 -> 0.076985951 | H16: ='Echo (tests 2, 3E)'!H23 -> 0.0076889968 | I16: ='Echo (tests 2, 3E)'!G24 -> -0.0078132979 | J16: ='Echo (tests 2, 3E)'!H24 -> 0.0051684631 | K16: =G16-I16 -> 0.084799249 | L16: =SQRT(H16^2+J16^2) -> 0.0092646469 | M16: =K16/L16 -> 9.1529931 | N16: =IF(OR(G16>2*H16,I16>2*J16),"yes","no") -> yes | O16: =IF(N16="no","NOT JUDGED",IF(K16>2*L16,"WIN",IF(K16<-2*L16,"LOSS","TIE"))) -> WIN
A17: kingston | B17: 2 | C17: 20 | D17: 0.3 | E17: 50 | F17: blind Qiskit | G17: ='Echo (tests 2, 3E)'!G23 -> 0.076985951 | H17: ='Echo (tests 2, 3E)'!H23 -> 0.0076889968 | I17: ='Echo (tests 2, 3E)'!G25 -> -0.0076747563 | J17: ='Echo (tests 2, 3E)'!H25 -> 0.0051593848 | K17: =G17-I17 -> 0.084660708 | L17: =SQRT(H17^2+J17^2) -> 0.0092595855 | M17: =K17/L17 -> 9.1430343 | N17: =IF(OR(G17>2*H17,I17>2*J17),"yes","no") -> yes | O17: =IF(N17="no","NOT JUDGED",IF(K17>2*L17,"WIN",IF(K17<-2*L17,"LOSS","TIE"))) -> WIN
A18: kingston | B18: 2 | C18: 20 | D18: 0.3 | E18: 100 | F18: zipcyc | G18: ='Echo (tests 2, 3E)'!G26 -> 0.001123366 | H18: ='Echo (tests 2, 3E)'!H26 -> 0.0053780088 | I18: ='Echo (tests 2, 3E)'!G27 -> -0.003071882 | J18: ='Echo (tests 2, 3E)'!H27 -> 0.0052287358 | K18: =G18-I18 -> 0.0041952481 | L18: =SQRT(H18^2+J18^2) -> 0.0075008437 | M18: =K18/L18 -> 0.55930349 | N18: =IF(OR(G18>2*H18,I18>2*J18),"yes","no") -> no | O18: =IF(N18="no","NOT JUDGED",IF(K18>2*L18,"WIN",IF(K18<-2*L18,"LOSS","TIE"))) -> NOT JUDGED
A19: kingston | B19: 2 | C19: 20 | D19: 0.3 | E19: 100 | F19: blind Qiskit | G19: ='Echo (tests 2, 3E)'!G26 -> 0.001123366 | H19: ='Echo (tests 2, 3E)'!H26 -> 0.0053780088 | I19: ='Echo (tests 2, 3E)'!G28 -> 0.012750078 | J19: ='Echo (tests 2, 3E)'!H28 -> 0.0051689886 | K19: =G19-I19 -> -0.011626712 | L19: =SQRT(H19^2+J19^2) -> 0.0074593178 | M19: =K19/L19 -> -1.558683 | N19: =IF(OR(G19>2*H19,I19>2*J19),"yes","no") -> yes | O19: =IF(N19="no","NOT JUDGED",IF(K19>2*L19,"WIN",IF(K19<-2*L19,"LOSS","TIE"))) -> TIE
A20: kingston | B20: 2 | C20: 36 | D20: 0 | E20: 24 | F20: zipcyc | G20: ='Echo (tests 2, 3E)'!G29 -> 0.42620836 | H20: ='Echo (tests 2, 3E)'!H29 -> 0.00805323 | I20: ='Echo (tests 2, 3E)'!G30 -> 0.095043097 | J20: ='Echo (tests 2, 3E)'!H30 -> 0.005658051 | K20: =G20-I20 -> 0.33116526 | L20: =SQRT(H20^2+J20^2) -> 0.009842157 | M20: =K20/L20 -> 33.64763 | N20: =IF(OR(G20>2*H20,I20>2*J20),"yes","no") -> yes | O20: =IF(N20="no","NOT JUDGED",IF(K20>2*L20,"WIN",IF(K20<-2*L20,"LOSS","TIE"))) -> WIN
A21: kingston | B21: 2 | C21: 36 | D21: 0 | E21: 24 | F21: blind Qiskit | G21: ='Echo (tests 2, 3E)'!G29 -> 0.42620836 | H21: ='Echo (tests 2, 3E)'!H29 -> 0.00805323 | I21: ='Echo (tests 2, 3E)'!G31 -> 0.0099290374 | J21: ='Echo (tests 2, 3E)'!H31 -> 0.0043336731 | K21: =G21-I21 -> 0.41627932 | L21: =SQRT(H21^2+J21^2) -> 0.0091452303 | M21: =K21/L21 -> 45.518736 | N21: =IF(OR(G21>2*H21,I21>2*J21),"yes","no") -> yes | O21: =IF(N21="no","NOT JUDGED",IF(K21>2*L21,"WIN",IF(K21<-2*L21,"LOSS","TIE"))) -> WIN
A22: kingston | B22: 2 | C22: 36 | D22: 0 | E22: 50 | F22: zipcyc | G22: ='Echo (tests 2, 3E)'!G32 -> 0.057047172 | H22: ='Echo (tests 2, 3E)'!H32 -> 0.0063498236 | I22: ='Echo (tests 2, 3E)'!G33 -> 0.0021479509 | J22: ='Echo (tests 2, 3E)'!H33 -> 0.0040321695 | K22: =G22-I22 -> 0.054899221 | L22: =SQRT(H22^2+J22^2) -> 0.0075218782 | M22: =K22/L22 -> 7.2986055 | N22: =IF(OR(G22>2*H22,I22>2*J22),"yes","no") -> yes | O22: =IF(N22="no","NOT JUDGED",IF(K22>2*L22,"WIN",IF(K22<-2*L22,"LOSS","TIE"))) -> WIN
A23: kingston | B23: 2 | C23: 36 | D23: 0 | E23: 50 | F23: blind Qiskit | G23: ='Echo (tests 2, 3E)'!G32 -> 0.057047172 | H23: ='Echo (tests 2, 3E)'!H32 -> 0.0063498236 | I23: ='Echo (tests 2, 3E)'!G34 -> -0.0034655592 | J23: ='Echo (tests 2, 3E)'!H34 -> 0.003776166 | K23: =G23-I23 -> 0.060512731 | L23: =SQRT(H23^2+J23^2) -> 0.0073878069 | M23: =K23/L23 -> 8.1908924 | N23: =IF(OR(G23>2*H23,I23>2*J23),"yes","no") -> yes | O23: =IF(N23="no","NOT JUDGED",IF(K23>2*L23,"WIN",IF(K23<-2*L23,"LOSS","TIE"))) -> WIN
A24: kingston | B24: 2 | C24: 36 | D24: 0 | E24: 100 | F24: zipcyc | G24: ='Echo (tests 2, 3E)'!G35 -> 0.004328508 | H24: ='Echo (tests 2, 3E)'!H35 -> 0.0044740315 | I24: ='Echo (tests 2, 3E)'!G36 -> -0.0038666438 | J24: ='Echo (tests 2, 3E)'!H36 -> 0.0038161352 | K24: =G24-I24 -> 0.0081951517 | L24: =SQRT(H24^2+J24^2) -> 0.0058804631 | M24: =K24/L24 -> 1.3936235 | N24: =IF(OR(G24>2*H24,I24>2*J24),"yes","no") -> no | O24: =IF(N24="no","NOT JUDGED",IF(K24>2*L24,"WIN",IF(K24<-2*L24,"LOSS","TIE"))) -> NOT JUDGED
A25: kingston | B25: 2 | C25: 36 | D25: 0 | E25: 100 | F25: blind Qiskit | G25: ='Echo (tests 2, 3E)'!G35 -> 0.004328508 | H25: ='Echo (tests 2, 3E)'!H35 -> 0.0044740315 | I25: ='Echo (tests 2, 3E)'!G37 -> -0.0030270147 | J25: ='Echo (tests 2, 3E)'!H37 -> 0.003907655 | K25: =G25-I25 -> 0.0073555226 | L25: =SQRT(H25^2+J25^2) -> 0.0059402631 | M25: =K25/L25 -> 1.2382486 | N25: =IF(OR(G25>2*H25,I25>2*J25),"yes","no") -> no | O25: =IF(N25="no","NOT JUDGED",IF(K25>2*L25,"WIN",IF(K25<-2*L25,"LOSS","TIE"))) -> NOT JUDGED
A26: kingston | B26: 2 | C26: 36 | D26: 0.1 | E26: 24 | F26: zipcyc | G26: ='Echo (tests 2, 3E)'!G38 -> 0.43608011 | H26: ='Echo (tests 2, 3E)'!H38 -> 0.0076687484 | I26: ='Echo (tests 2, 3E)'!G39 -> 0.11138472 | J26: ='Echo (tests 2, 3E)'!H39 -> 0.0057716693 | K26: =G26-I26 -> 0.32469539 | L26: =SQRT(H26^2+J26^2) -> 0.0095980137 | M26: =K26/L26 -> 33.829436 | N26: =IF(OR(G26>2*H26,I26>2*J26),"yes","no") -> yes | O26: =IF(N26="no","NOT JUDGED",IF(K26>2*L26,"WIN",IF(K26<-2*L26,"LOSS","TIE"))) -> WIN
A27: kingston | B27: 2 | C27: 36 | D27: 0.1 | E27: 24 | F27: blind Qiskit | G27: ='Echo (tests 2, 3E)'!G38 -> 0.43608011 | H27: ='Echo (tests 2, 3E)'!H38 -> 0.0076687484 | I27: ='Echo (tests 2, 3E)'!G40 -> -0.002974403 | J27: ='Echo (tests 2, 3E)'!H40 -> 0.0041879954 | K27: =G27-I27 -> 0.43905452 | L27: =SQRT(H27^2+J27^2) -> 0.0087377919 | M27: =K27/L27 -> 50.247766 | N27: =IF(OR(G27>2*H27,I27>2*J27),"yes","no") -> yes | O27: =IF(N27="no","NOT JUDGED",IF(K27>2*L27,"WIN",IF(K27<-2*L27,"LOSS","TIE"))) -> WIN
A28: kingston | B28: 2 | C28: 36 | D28: 0.1 | E28: 50 | F28: zipcyc | G28: ='Echo (tests 2, 3E)'!G41 -> 0.062284829 | H28: ='Echo (tests 2, 3E)'!H41 -> 0.0058981902 | I28: ='Echo (tests 2, 3E)'!G42 -> -0.00034374105 | J28: ='Echo (tests 2, 3E)'!H42 -> 0.0040013162 | K28: =G28-I28 -> 0.06262857 | L28: =SQRT(H28^2+J28^2) -> 0.0071273543 | M28: =K28/L28 -> 8.7870712 | N28: =IF(OR(G28>2*H28,I28>2*J28),"yes","no") -> yes | O28: =IF(N28="no","NOT JUDGED",IF(K28>2*L28,"WIN",IF(K28<-2*L28,"LOSS","TIE"))) -> WIN
A29: kingston | B29: 2 | C29: 36 | D29: 0.1 | E29: 50 | F29: blind Qiskit | G29: ='Echo (tests 2, 3E)'!G41 -> 0.062284829 | H29: ='Echo (tests 2, 3E)'!H41 -> 0.0058981902 | I29: ='Echo (tests 2, 3E)'!G43 -> -0.0018041237 | J29: ='Echo (tests 2, 3E)'!H43 -> 0.0038655393 | K29: =G29-I29 -> 0.064088953 | L29: =SQRT(H29^2+J29^2) -> 0.007052024 | M29: =K29/L29 -> 9.0880225 | N29: =IF(OR(G29>2*H29,I29>2*J29),"yes","no") -> yes | O29: =IF(N29="no","NOT JUDGED",IF(K29>2*L29,"WIN",IF(K29<-2*L29,"LOSS","TIE"))) -> WIN
A30: kingston | B30: 2 | C30: 36 | D30: 0.1 | E30: 100 | F30: zipcyc | G30: ='Echo (tests 2, 3E)'!G44 -> 0.00025759918 | H30: ='Echo (tests 2, 3E)'!H44 -> 0.0043245863 | I30: ='Echo (tests 2, 3E)'!G45 -> -0.005905794 | J30: ='Echo (tests 2, 3E)'!H45 -> 0.0038678314 | K30: =G30-I30 -> 0.0061633932 | L30: =SQRT(H30^2+J30^2) -> 0.0058019106 | M30: =K30/L30 -> 1.0623041 | N30: =IF(OR(G30>2*H30,I30>2*J30),"yes","no") -> no | O30: =IF(N30="no","NOT JUDGED",IF(K30>2*L30,"WIN",IF(K30<-2*L30,"LOSS","TIE"))) -> NOT JUDGED
A31: kingston | B31: 2 | C31: 36 | D31: 0.1 | E31: 100 | F31: blind Qiskit | G31: ='Echo (tests 2, 3E)'!G44 -> 0.00025759918 | H31: ='Echo (tests 2, 3E)'!H44 -> 0.0043245863 | I31: ='Echo (tests 2, 3E)'!G46 -> -0.0054052508 | J31: ='Echo (tests 2, 3E)'!H46 -> 0.0038257367 | K31: =G31-I31 -> 0.00566285 | L31: =SQRT(H31^2+J31^2) -> 0.0057739335 | M31: =K31/L31 -> 0.98076121 | N31: =IF(OR(G31>2*H31,I31>2*J31),"yes","no") -> no | O31: =IF(N31="no","NOT JUDGED",IF(K31>2*L31,"WIN",IF(K31<-2*L31,"LOSS","TIE"))) -> NOT JUDGED
A32: kingston | B32: 2 | C32: 36 | D32: 0.3 | E32: 24 | F32: zipcyc | G32: ='Echo (tests 2, 3E)'!G47 -> 0.43825853 | H32: ='Echo (tests 2, 3E)'!H47 -> 0.007192361 | I32: ='Echo (tests 2, 3E)'!G48 -> 0.10414818 | J32: ='Echo (tests 2, 3E)'!H48 -> 0.005124049 | K32: =G32-I32 -> 0.33411035 | L32: =SQRT(H32^2+J32^2) -> 0.0088309646 | M32: =K32/L32 -> 37.833959 | N32: =IF(OR(G32>2*H32,I32>2*J32),"yes","no") -> yes | O32: =IF(N32="no","NOT JUDGED",IF(K32>2*L32,"WIN",IF(K32<-2*L32,"LOSS","TIE"))) -> WIN
A33: kingston | B33: 2 | C33: 36 | D33: 0.3 | E33: 24 | F33: blind Qiskit | G33: ='Echo (tests 2, 3E)'!G47 -> 0.43825853 | H33: ='Echo (tests 2, 3E)'!H47 -> 0.007192361 | I33: ='Echo (tests 2, 3E)'!G49 -> 0.0044961196 | J33: ='Echo (tests 2, 3E)'!H49 -> 0.0040844603 | K33: =G33-I33 -> 0.43376241 | L33: =SQRT(H33^2+J33^2) -> 0.0082712074 | M33: =K33/L33 -> 52.442454 | N33: =IF(OR(G33>2*H33,I33>2*J33),"yes","no") -> yes | O33: =IF(N33="no","NOT JUDGED",IF(K33>2*L33,"WIN",IF(K33<-2*L33,"LOSS","TIE"))) -> WIN
A34: kingston | B34: 2 | C34: 36 | D34: 0.3 | E34: 50 | F34: zipcyc | G34: ='Echo (tests 2, 3E)'!G50 -> 0.048357063 | H34: ='Echo (tests 2, 3E)'!H50 -> 0.0052381423 | I34: ='Echo (tests 2, 3E)'!G51 -> -0.0022614072 | J34: ='Echo (tests 2, 3E)'!H51 -> 0.0038907373 | K34: =G34-I34 -> 0.05061847 | L34: =SQRT(H34^2+J34^2) -> 0.0065250265 | M34: =K34/L34 -> 7.7575884 | N34: =IF(OR(G34>2*H34,I34>2*J34),"yes","no") -> yes | O34: =IF(N34="no","NOT JUDGED",IF(K34>2*L34,"WIN",IF(K34<-2*L34,"LOSS","TIE"))) -> WIN
A35: kingston | B35: 2 | C35: 36 | D35: 0.3 | E35: 50 | F35: blind Qiskit | G35: ='Echo (tests 2, 3E)'!G50 -> 0.048357063 | H35: ='Echo (tests 2, 3E)'!H50 -> 0.0052381423 | I35: ='Echo (tests 2, 3E)'!G52 -> 0.0029459715 | J35: ='Echo (tests 2, 3E)'!H52 -> 0.0038872111 | K35: =G35-I35 -> 0.045411092 | L35: =SQRT(H35^2+J35^2) -> 0.0065229245 | M35: =K35/L35 -> 6.9617687 | N35: =IF(OR(G35>2*H35,I35>2*J35),"yes","no") -> yes | O35: =IF(N35="no","NOT JUDGED",IF(K35>2*L35,"WIN",IF(K35<-2*L35,"LOSS","TIE"))) -> WIN
A36: kingston | B36: 2 | C36: 36 | D36: 0.3 | E36: 100 | F36: zipcyc | G36: ='Echo (tests 2, 3E)'!G53 -> 0.0039193248 | H36: ='Echo (tests 2, 3E)'!H53 -> 0.0039610141 | I36: ='Echo (tests 2, 3E)'!G54 -> 0.0030375974 | J36: ='Echo (tests 2, 3E)'!H54 -> 0.0039050355 | K36: =G36-I36 -> 0.00088172741 | L36: =SQRT(H36^2+J36^2) -> 0.0055622779 | M36: =K36/L36 -> 0.15851912 | N36: =IF(OR(G36>2*H36,I36>2*J36),"yes","no") -> no | O36: =IF(N36="no","NOT JUDGED",IF(K36>2*L36,"WIN",IF(K36<-2*L36,"LOSS","TIE"))) -> NOT JUDGED
A37: kingston | B37: 2 | C37: 36 | D37: 0.3 | E37: 100 | F37: blind Qiskit | G37: ='Echo (tests 2, 3E)'!G53 -> 0.0039193248 | H37: ='Echo (tests 2, 3E)'!H53 -> 0.0039610141 | I37: ='Echo (tests 2, 3E)'!G55 -> 0.0023447329 | J37: ='Echo (tests 2, 3E)'!H55 -> 0.0039291679 | K37: =G37-I37 -> 0.0015745919 | L37: =SQRT(H37^2+J37^2) -> 0.0055792467 | M37: =K37/L37 -> 0.28222303 | N37: =IF(OR(G37>2*H37,I37>2*J37),"yes","no") -> no | O37: =IF(N37="no","NOT JUDGED",IF(K37>2*L37,"WIN",IF(K37<-2*L37,"LOSS","TIE"))) -> NOT JUDGED
A38: kingston | B38: 3E | C38: 40 | D38: 0 | E38: 24 | F38: zipcyc | G38: ='Echo (tests 2, 3E)'!G56 -> 0.17266651 | H38: ='Echo (tests 2, 3E)'!H56 -> 0.0056066521 | I38: ='Echo (tests 2, 3E)'!G57 -> 0.042912807 | J38: ='Echo (tests 2, 3E)'!H57 -> 0.0042404459 | K38: =G38-I38 -> 0.12975371 | L38: =SQRT(H38^2+J38^2) -> 0.0070296464 | M38: =K38/L38 -> 18.45807 | N38: =IF(OR(G38>2*H38,I38>2*J38),"yes","no") -> yes | O38: =IF(N38="no","NOT JUDGED",IF(K38>2*L38,"WIN",IF(K38<-2*L38,"LOSS","TIE"))) -> WIN
A39: kingston | B39: 3E | C39: 40 | D39: 0 | E39: 24 | F39: blind Qiskit | G39: ='Echo (tests 2, 3E)'!G56 -> 0.17266651 | H39: ='Echo (tests 2, 3E)'!H56 -> 0.0056066521 | I39: ='Echo (tests 2, 3E)'!G58 -> -0.0043778981 | J39: ='Echo (tests 2, 3E)'!H58 -> 0.0038926023 | K39: =G39-I39 -> 0.17704441 | L39: =SQRT(H39^2+J39^2) -> 0.0068254597 | M39: =K39/L39 -> 25.938826 | N39: =IF(OR(G39>2*H39,I39>2*J39),"yes","no") -> yes | O39: =IF(N39="no","NOT JUDGED",IF(K39>2*L39,"WIN",IF(K39<-2*L39,"LOSS","TIE"))) -> WIN
A40: kingston | B40: 3E | C40: 40 | D40: 0 | E40: 50 | F40: zipcyc | G40: ='Echo (tests 2, 3E)'!G59 -> -0.0207516 | H40: ='Echo (tests 2, 3E)'!H59 -> 0.004345488 | I40: ='Echo (tests 2, 3E)'!G60 -> -0.0010590484 | J40: ='Echo (tests 2, 3E)'!H60 -> 0.003765932 | K40: =G40-I40 -> -0.019692552 | L40: =SQRT(H40^2+J40^2) -> 0.0057502617 | M40: =K40/L40 -> -3.4246358 | N40: =IF(OR(G40>2*H40,I40>2*J40),"yes","no") -> no | O40: =IF(N40="no","NOT JUDGED",IF(K40>2*L40,"WIN",IF(K40<-2*L40,"LOSS","TIE"))) -> NOT JUDGED
...

Sheet Parity (test 3P)
A1: device | B1: n | C1: L | D1: n x L | E1: arm | F1: P(|+..+>) | G1: P(|-..->) | H1: P(|-+..+>) | I1: P(|+-..->) | J1: ref Neel | K1: ref anti-Neel | L1: ref Neel f | M1: ref anti-Neel f | N1: num (signed mean) | O1: ref (signed mean) | P1: rho_P = num / ref | Q1: SE | R1: signal / SE | S1: 2Q gates | T1: duration (us)
A2: kingston | B2: 20 | C2: 2 | D2: =B2*C2 -> 40 | E2: rule | F2: 0.264 | G2: 0.25 | H2: -0.336 | I2: -0.296 | J2: 0.6 | K2: 0.564 | L2: -0.538 | M2: -0.588 | N2: =(F2+G2-H2-I2)/4 -> 0.2865 | O2: =(1*J2+1*K2-(1)*L2-(1)*M2)/4 -> 0.5725 | P2: =IF(O2<>0,N2/O2,"n/a") -> 0.50043668 | Q2: 0.028768461 | R2: =IF(ISNUMBER(P2),P2/Q2,"n/a") -> 17.395324 | S2: 40 | T2: 2.668
A3: kingston | B3: 20 | C3: 4 | D3: =B3*C3 -> 80 | E3: rule | F3: 0.21 | G3: 0.224 | H3: -0.236 | I3: -0.16 | J3: 0.55 | K3: 0.516 | L3: -0.548 | M3: -0.582 | N3: =(F3+G3-H3-I3)/4 -> 0.2075 | O3: =(1*J3+1*K3-(1)*L3-(1)*M3)/4 -> 0.549 | P3: =IF(O3<>0,N3/O3,"n/a") -> 0.37795993 | Q3: 0.029593338 | R3: =IF(ISNUMBER(P3),P3/Q3,"n/a") -> 12.771791 | S3: 80 | T3: 3.092
A4: kingston | B4: 20 | C4: 8 | D4: =B4*C4 -> 160 | E4: rule | F4: 0.102 | G4: 0.068 | H4: -0.112 | I4: -0.046 | J4: 0.612 | K4: 0.596 | L4: -0.546 | M4: -0.554 | N4: =(F4+G4-H4-I4)/4 -> 0.082 | O4: =(1*J4+1*K4-(1)*L4-(1)*M4)/4 -> 0.577 | P4: =IF(O4<>0,N4/O4,"n/a") -> 0.14211438 | Q4: 0.027485316 | R4: =IF(ISNUMBER(P4),P4/Q4,"n/a") -> 5.1705568 | S4: 160 | T4: 3.94
A5: kingston | B5: 20 | C5: 2 | D5: =B5*C5 -> 40 | E5: zipcyc | F5: 0.23 | G5: 0.188 | H5: -0.232 | I5: -0.17 | J5: 0.572 | K5: 0.544 | L5: -0.574 | M5: -0.626 | N5: =(F5+G5-H5-I5)/4 -> 0.205 | O5: =(1*J5+1*K5-(1)*L5-(1)*M5)/4 -> 0.579 | P5: =IF(O5<>0,N5/O5,"n/a") -> 0.35405872 | Q5: 0.027855339 | R5: =IF(ISNUMBER(P5),P5/Q5,"n/a") -> 12.710624 | S5: 92 | T5: 3.292
A6: kingston | B6: 20 | C6: 4 | D6: =B6*C6 -> 80 | E6: zipcyc | F6: 0.074 | G6: 0.06 | H6: -0.078 | I6: -0.076 | J6: 0.566 | K6: 0.564 | L6: -0.546 | M6: -0.59 | N6: =(F6+G6-H6-I6)/4 -> 0.072 | O6: =(1*J6+1*K6-(1)*L6-(1)*M6)/4 -> 0.5665 | P6: =IF(O6<>0,N6/O6,"n/a") -> 0.1270962 | Q6: 0.02799053 | R6: =IF(ISNUMBER(P6),P6/Q6,"n/a") -> 4.540686 | S6: 184 | T6: 4.34
A7: kingston | B7: 20 | C7: 8 | D7: =B7*C7 -> 160 | E7: zipcyc | F7: 0.034 | G7: 0.02 | H7: -0.036 | I7: -0.004 | J7: 0.588 | K7: 0.546 | L7: -0.58 | M7: -0.544 | N7: =(F7+G7-H7-I7)/4 -> 0.0235 | O7: =(1*J7+1*K7-(1)*L7-(1)*M7)/4 -> 0.5645 | P7: =IF(O7<>0,N7/O7,"n/a") -> 0.041629761 | Q7: 0.02801603 | R7: =IF(ISNUMBER(P7),P7/Q7,"n/a") -> 1.4859265 | S7: 368 | T7: 6.436
A8: kingston | B8: 20 | C8: 2 | D8: =B8*C8 -> 40 | E8: blind Qiskit | F8: 0.038 | G8: -0.02 | H8: 0.072 | I8: 0.058 | J8: 0.408 | K8: 0.518 | L8: -0.424 | M8: -0.5 | N8: =(F8+G8-H8-I8)/4 -> -0.028 | O8: =(1*J8+1*K8-(1)*L8-(1)*M8)/4 -> 0.4625 | P8: =IF(O8<>0,N8/O8,"n/a") -> -0.060540541 | Q8: 0.034191485 | R8: =IF(ISNUMBER(P8),P8/Q8,"n/a") -> -1.7706321 | S8: 40 | T8: 5.196
A9: kingston | B9: 20 | C9: 4 | D9: =B9*C9 -> 80 | E9: blind Qiskit | F9: -0.02 | G9: -0.012 | H9: 0.002 | I9: 0.036 | J9: 0.448 | K9: 0.532 | L9: -0.418 | M9: -0.5 | N9: =(F9+G9-H9-I9)/4 -> -0.0175 | O9: =(1*J9+1*K9-(1)*L9-(1)*M9)/4 -> 0.4745 | P9: =IF(O9<>0,N9/O9,"n/a") -> -0.036880927 | Q9: 0.033332043 | R9: =IF(ISNUMBER(P9),P9/Q9,"n/a") -> -1.1064707 | S9: 80 | T9: 8.148
A10: kingston | B10: 20 | C10: 8 | D10: =B10*C10 -> 160 | E10: blind Qiskit | F10: 0.032 | G10: -0.036 | H10: 0.036 | I10: 0.034 | J10: 0.426 | K10: 0.502 | L10: -0.478 | M10: -0.482 | N10: =(F10+G10-H10-I10)/4 -> -0.0185 | O10: =(1*J10+1*K10-(1)*L10-(1)*M10)/4 -> 0.472 | P10: =IF(O10<>0,N10/O10,"n/a") -> -0.039194915 | Q10: 0.0334987 | R10: =IF(ISNUMBER(P10),P10/Q10,"n/a") -> -1.1700429 | S10: 160 | T10: 14.052
A11: kingston | B11: 36 | C11: 1 | D11: =B11*C11 -> 36 | E11: rule | F11: 0.192 | G11: 0.172 | H11: -0.176 | I11: -0.144 | J11: 0.346 | K11: 0.268 | L11: -0.296 | M11: -0.35 | N11: =(F11+G11-H11-I11)/4 -> 0.171 | O11: =(1*J11+1*K11-(1)*L11-(1)*M11)/4 -> 0.315 | P11: =IF(O11<>0,N11/O11,"n/a") -> 0.54285714 | Q11: 0.055794554 | R11: =IF(ISNUMBER(P11),P11/Q11,"n/a") -> 9.7295723 | S11: 36 | T11: 2.484
A12: kingston | B12: 36 | C12: 2 | D12: =B12*C12 -> 72 | E12: rule | F12: 0.186 | G12: 0.13 | H12: -0.162 | I12: -0.174 | J12: 0.298 | K12: 0.298 | L12: -0.28 | M12: -0.326 | N12: =(F12+G12-H12-I12)/4 -> 0.163 | O12: =(1*J12+1*K12-(1)*L12-(1)*M12)/4 -> 0.3005 | P12: =IF(O12<>0,N12/O12,"n/a") -> 0.54242928 | Q12: 0.058605364 | R12: =IF(ISNUMBER(P12),P12/Q12,"n/a") -> 9.2556252 | S12: 72 | T12: 2.724
A13: kingston | B13: 36 | C13: 4 | D13: =B13*C13 -> 144 | E13: rule | F13: 0.15 | G13: 0.08 | H13: -0.104 | I13: -0.062 | J13: 0.27 | K13: 0.324 | L13: -0.298 | M13: -0.24 | N13: =(F13+G13-H13-I13)/4 -> 0.099 | O13: =(1*J13+1*K13-(1)*L13-(1)*M13)/4 -> 0.283 | P13: =IF(O13<>0,N13/O13,"n/a") -> 0.34982332 | Q13: 0.058639289 | R13: =IF(ISNUMBER(P13),P13/Q13,"n/a") -> 5.9656815 | S13: 144 | T13: 3.204
... A85: marrakesh | B85: 96 | C85: 2 | D85: =B85*C85 -> 192 | E85: blind Qiskit | F85: 0.014 | G85: -0.0215 | H85: -0.015 | I85: 0.0115 | J85: -0.0085 | K85: 0.001 | L85: 0.0035 | M85: -0.008 | N85: =(F85+G85-H85-I85)/4 -> -0.001 | O85: =(1*J85+1*K85-(1)*L85-(1)*M85)/4 -> -0.00075 | P85: =IF(O85<>0,N85/O85,"n/a") -> 1.3333333 | Q85: 17.567196 | R85: =IF(ISNUMBER(P85),P85/Q85,"n/a") -> 0.07589904 | S85: 192 | T85: 16.156
A87: Reference signs: Neel and anti-Neel have parity (-1)^(n/2); with the first bit flipped, the opposite. The ref column is the readout factor (1 for a perfect readout).

Sheet Parity Vstar
A1: device | B1: arm | C1: n | D1: V* (fit) | E1: SE | F1: declared V* | G1: band low | H1: band high | I1: P-A verdict (n 20, 36)
A2: kingston | B2: rule | C2: 20 | D2: 72.64236 | E2: 3.8647915 | F2: 171 | G2: =0.8*F2-2*E2 -> 129.07042 | H2: =1.2*F2+2*E2 -> 212.92958 | I2: =IF(D2<G2,"BELOW",IF(D2>H2,"ABOVE","INSIDE")) -> BELOW
A3: kingston | B3: rule | C3: 36 | D3: 105.77128 | E3: 11.222864 | F3: 171 | G3: =0.8*F3-2*E3 -> 114.35427 | H3: =1.2*F3+2*E3 -> 227.64573 | I3: =IF(D3<G3,"BELOW",IF(D3>H3,"ABOVE","INSIDE")) -> BELOW
A4: kingston | B4: rule | C4: 40 | D4: 3.266904 | E4: 3091.6378
A5: kingston | B5: rule | C5: 72 | D5: 27.426098 | E5: 16.83297
A6: kingston | B6: zipcyc | C6: 20 | D6: 38.93112 | E6: 2.3757308 | F6: 47.5 | G6: =0.8*F6-2*E6 -> 33.248538 | H6: =1.2*F6+2*E6 -> 61.751462 | I6: =IF(D6<G6,"BELOW",IF(D6>H6,"ABOVE","INSIDE")) -> INSIDE
A7: kingston | B7: zipcyc | C7: 36 | D7: 63.209294 | E7: 6.8681547 | F7: 47.5 | G7: =0.8*F7-2*E7 -> 24.263691 | H7: =1.2*F7+2*E7 -> 70.736309 | I7: =IF(D7<G7,"BELOW",IF(D7>H7,"ABOVE","INSIDE")) -> INSIDE
A8: kingston | B8: zipcyc | C8: 40 | D8: 19.89899 | E8: 4.0383039
A9: kingston | B9: zipcyc | C9: 72 | D9: 28.839455 | E9: 14.746002
A10: kingston | B10: blind Qiskit | C10: 20
A11: kingston | B11: blind Qiskit | C11: 36 | D11: 8.3649554 | E11: 7.0096951
A12: kingston | B12: blind Qiskit | C12: 40 | D12: 15.366247 | E12: 4.7186983
A13: kingston | B13: blind Qiskit | C13: 72 | D13: 18.963885 | E13: 27.356944
A14: kingston | B14: rule | C14: 88 | D14: 50.826646 | E14: 15.516569
A15: kingston | B15: zipcyc | C15: 88
A16: kingston | B16: blind Qiskit | C16: 88
A17: marrakesh | B17: rule | C17: 20 | D17: 59.81987 | E17: 4.4027279 | F17: 113 | G17: =0.8*F17-2*E17 -> 81.594544 | H17: =1.2*F17+2*E17 -> 144.40546 | I17: =IF(D17<G17,"BELOW",IF(D17>H17,"ABOVE","INSIDE")) -> BELOW
A18: marrakesh | B18: rule | C18: 36 | D18: 76.385917 | E18: 13.948522 | F18: 113 | G18: =0.8*F18-2*E18 -> 62.502957 | H18: =1.2*F18+2*E18 -> 163.49704 | I18: =IF(D18<G18,"BELOW",IF(D18>H18,"ABOVE","INSIDE")) -> INSIDE
A19: marrakesh | B19: rule | C19: 40 | D19: 2.0895141 | E19: 4190308.4
A20: marrakesh | B20: rule | C20: 72 | D20: 83.714661 | E20: 481.52965
A21: marrakesh | B21: zipcyc | C21: 20 | D21: 29.58114 | E21: 2.9856503 | F21: 31.4 | G21: =0.8*F21-2*E21 -> 19.148699 | H21: =1.2*F21+2*E21 -> 43.651301 | I21: =IF(D21<G21,"BELOW",IF(D21>H21,"ABOVE","INSIDE")) -> INSIDE
A22: marrakesh | B22: zipcyc | C22: 36 | D22: 29.447773 | E22: 6.1876458 | F22: 31.4 | G22: =0.8*F22-2*E22 -> 12.744708 | H22: =1.2*F22+2*E22 -> 50.055292 | I22: =IF(D22<G22,"BELOW",IF(D22>H22,"ABOVE","INSIDE")) -> INSIDE
A23: marrakesh | B23: zipcyc | C23: 40
A24: marrakesh | B24: zipcyc | C24: 72 | D24: 34.884552 | E24: 70.864905
A25: marrakesh | B25: blind Qiskit | C25: 20 | D25: 19.327792 | E25: 2.5937351
A26: marrakesh | B26: blind Qiskit | C26: 36 | D26: 33.683413 | E26: 6.3032086
A27: marrakesh | B27: blind Qiskit | C27: 40 | D27: 10.376334 | E27: 33.176471
A28: marrakesh | B28: blind Qiskit | C28: 72 | D28: 78.875169 | E28: 208.77941
A29: marrakesh | B29: rule | C29: 96 | D29: 594.05011 | E29: 3797.4429
A30: marrakesh | B30: zipcyc | C30: 96 | D30: 51.146673 | E30: 207.20783
A31: marrakesh | B31: blind Qiskit | C31: 96 | D31: 9.6 | E31: 22398.24
A33: Declared V*_rule = 2 L* of 2026-10-29 (kingston 171, marrakesh 113); V*_zipcyc = V*_rule / 3.6. Band +-20 % widened by 2 SE.

Sheet QELM A (kingston)
A1: arm | B1: S (shots) | C1: test accuracy | D1: declared mean | E1: declared low (99 %) | F1: declared high (99 %) | G1: inside band? | H1: lambda X (median) | I1: lambda Y | J1: lambda Z | K1: declared lambda | L1: chi2/dof median | M1: Q1
A2: rule | B2: 16 | C2: 0.695 | D2: 0.662775 | E2: 0.564975 | F2: 0.75 | G2: =IF(AND(C2>=E2,C2<=F2),"INSIDE","OUTSIDE") -> INSIDE | H2: 0.70289174 | I2: 0.65618116 | J2: 0.8776741 | K2: 0.79159741 | L2: 2.8739564 | M2: =IF(L2<=2,"HOLDS","FAILS") -> FAILS
A3: rule | B3: 32 | C3: 0.75 | D3: 0.714375 | E3: 0.61995 | F3: 0.79505 | G3: =IF(AND(C3>=E3,C3<=F3),"INSIDE","OUTSIDE") -> INSIDE | H3: 0.70289174 | I3: 0.65618116 | J3: 0.8776741 | K3: 0.79159741 | L3: 2.8739564 | M3: =IF(L3<=2,"HOLDS","FAILS") -> FAILS
A4: rule | B4: 64 | C4: 0.74 | D4: 0.7642875 | E4: 0.645 | F4: 0.845025 | G4: =IF(AND(C4>=E4,C4<=F4),"INSIDE","OUTSIDE") -> INSIDE | H4: 0.70289174 | I4: 0.65618116 | J4: 0.8776741 | K4: 0.79159741 | L4: 2.8739564 | M4: =IF(L4<=2,"HOLDS","FAILS") -> FAILS
A5: rule | B5: 125 | C5: 0.745 | D5: 0.7995125 | E5: 0.71485 | F5: 0.885 | G5: =IF(AND(C5>=E5,C5<=F5),"INSIDE","OUTSIDE") -> INSIDE | H5: 0.70289174 | I5: 0.65618116 | J5: 0.8776741 | K5: 0.79159741 | L5: 2.8739564 | M5: =IF(L5<=2,"HOLDS","FAILS") -> FAILS
A6: rule | B6: 250 | C6: 0.81 | D6: 0.8300875 | E6: 0.74495 | F6: 0.9 | G6: =IF(AND(C6>=E6,C6<=F6),"INSIDE","OUTSIDE") -> INSIDE | H6: 0.70289174 | I6: 0.65618116 | J6: 0.8776741 | K6: 0.79159741 | L6: 2.8739564 | M6: =IF(L6<=2,"HOLDS","FAILS") -> FAILS
A7: zipcyc | B7: 16 | C7: 0.595 | D7: 0.5751625 | E7: 0.475 | F7: 0.680025 | G7: =IF(AND(C7>=E7,C7<=F7),"INSIDE","OUTSIDE") -> INSIDE | H7: 0.34894931 | I7: 0.37721633 | J7: 0.68297879 | K7: 0.431405 | L7: 1.7252748 | M7: =IF(L7<=2,"HOLDS","FAILS") -> HOLDS
A8: zipcyc | B8: 32 | C8: 0.6 | D8: 0.6183625 | E8: 0.529975 | F8: 0.710025 | G8: =IF(AND(C8>=E8,C8<=F8),"INSIDE","OUTSIDE") -> INSIDE | H8: 0.34894931 | I8: 0.37721633 | J8: 0.68297879 | K8: 0.431405 | L8: 1.7252748 | M8: =IF(L8<=2,"HOLDS","FAILS") -> HOLDS
A9: zipcyc | B9: 64 | C9: 0.65 | D9: 0.6752625 | E9: 0.575 | F9: 0.78 | G9: =IF(AND(C9>=E9,C9<=F9),"INSIDE","OUTSIDE") -> INSIDE | H9: 0.34894931 | I9: 0.37721633 | J9: 0.68297879 | K9: 0.431405 | L9: 1.7252748 | M9: =IF(L9<=2,"HOLDS","FAILS") -> HOLDS
A10: zipcyc | B10: 125 | C10: 0.65 | D10: 0.7226625 | E10: 0.61 | F10: 0.81005 | G10: =IF(AND(C10>=E10,C10<=F10),"INSIDE","OUTSIDE") -> INSIDE | H10: 0.34894931 | I10: 0.37721633 | J10: 0.68297879 | K10: 0.431405 | L10: 1.7252748 | M10: =IF(L10<=2,"HOLDS","FAILS") -> HOLDS
A11: zipcyc | B11: 250 | C11: 0.715 | D11: 0.7700125 | E11: 0.689925 | F11: 0.845025 | G11: =IF(AND(C11>=E11,C11<=F11),"INSIDE","OUTSIDE") -> INSIDE | H11: 0.34894931 | I11: 0.37721633 | J11: 0.68297879 | K11: 0.431405 | L11: 1.7252748 | M11: =IF(L11<=2,"HOLDS","FAILS") -> HOLDS
A12: blind Qiskit | B12: 16 | C12: 0.695 | D12: 0.574275 | E12: 0.464975 | F12: 0.675 | G12: =IF(AND(C12>=E12,C12<=F12),"INSIDE","OUTSIDE") -> OUTSIDE | H12: 0.56708885 | I12: 0.48828015 | J12: 0.80562601 | K12: 0.42162611 | L12: 3.4540299 | M12: =IF(L12<=2,"HOLDS","FAILS") -> FAILS
A13: blind Qiskit | B13: 32 | C13: 0.73 | D13: 0.6164375 | E13: 0.51495 | F13: 0.710025 | G13: =IF(AND(C13>=E13,C13<=F13),"INSIDE","OUTSIDE") -> OUTSIDE | H13: 0.56708885 | I13: 0.48828015 | J13: 0.80562601 | K13: 0.42162611 | L13: 3.4540299 | M13: =IF(L13<=2,"HOLDS","FAILS") -> FAILS
... A16: blind Qiskit | B16: 250 | C16: 0.75 | D16: 0.769875 | E16: 0.679975 | F16: 0.855075 | G16: =IF(AND(C16>=E16,C16<=F16),"INSIDE","OUTSIDE") -> INSIDE | H16: 0.56708885 | I16: 0.48828015 | J16: 0.80562601 | K16: 0.42162611 | L16: 3.4540299 | M16: =IF(L16<=2,"HOLDS","FAILS") -> FAILS
A18: Q3a rule vs zipcyc (one-sided McNemar, Holm)
A19: S64 | B19: rule only right | C19: 47 | D19: zipcyc only right | E19: 29 | F19: p (one-sided) | G19: 0.025226205
A20: S250 | B20: rule only right | C20: 37 | D20: zipcyc only right | E20: 18 | F20: p (one-sided) | G20: 0.0072269168
A21: Q3a verdict: WIN (Holm [True, True]); Q3b (rule vs blind Qiskit, reported): not
A22: R baselines: raw x 0.555, noiseless ceiling 0.840, majority 0.510
